Workbook

Sheet Constituency_Upazila_Map
A1: Constituency | B1: Upazila | C1: District
A2: Panchagarh-1 | B2: Panchagarh Sadar | C2: Panchagarh
A3: Panchagarh-1 | B3: Tetulia | C3: Panchagarh
A4: Panchagarh-1 | B4: Atwari | C4: Panchagarh
A5: Panchagarh-2 | B5: Boda | C5: Panchagarh
A6: Panchagarh-2 | B6: Debiganj | C6: Panchagarh
A7: Thakurgaon-1 | B7: Thakurgaon Sadar | C7: Thakurgaon
A8: Thakurgaon-2 | B8: Baliadangi | C8: Thakurgaon
A9: Thakurgaon-2 | B9: Haripur | C9: Thakurgaon
A10: Thakurgaon-2 | B10: Ranisankail | C10: Thakurgaon
A11: Thakurgaon-3 | B11: Pirganj | C11: Thakurgaon
A12: Thakurgaon-3 | B12: Ranisankail | C12: Thakurgaon
... A497: Bandarban-1 | B497: Ruma | C497: Bandarban

Sheet Population_data
A1: District | B1: Upazila | C1: Area_sqkm | D1: Population | E1: Population_Density | F1: Household_Size | G1: Literacy_Rate | H1: Merge_Key
A2: Barguna | B2: Amtali | C2: 483 | D2: 214436 | E2: 443.97 | F2: 3.97 | G2: 73.23 | H2: =TRIM(A2)&"|"&TRIM(B2) -> Barguna|Amtali
A3: Barguna | B3: Bamna | C3: 99.85 | D3: 78942 | E3: 790.61 | F3: 3.76 | G3: 82.51 | H3: =TRIM(A3)&"|"&TRIM(B3) -> Barguna|Bamna
A4: Barguna | B4: Barguna Sadar | C4: 454.6 | D4: 294350 | E4: 647.49 | F4: 3.95 | G4: 82.28 | H4: =TRIM(A4)&"|"&TRIM(B4) -> Barguna|Barguna Sadar
A5: Barguna | B5: Betagi | C5: 135.2 | D5: 125464 | E5: 927.99 | F5: 4 | G5: 82.5 | H5: =TRIM(A5)&"|"&TRIM(B5) -> Barguna|Betagi
A6: Barguna | B6: Patharghata | C6: 387.5 | D6: 177875 | E6: 459.03 | F6: 3.76 | G6: 84.67 | H6: =TRIM(A6)&"|"&TRIM(B6) -> Barguna|Patharghata
A7: Barguna | B7: Taltali | C7: 336 | D7: 119394 | E7: 355.34 | F7: 4.03 | G7: 80.77 | H7: =TRIM(A7)&"|"&TRIM(B7) -> Barguna|Taltali
A8: Barisal | B8: Agailjhara | C8: 161.82 | D8: 156415 | E8: 966.6 | F8: 4.04 | G8: 82.1 | H8: =TRIM(A8)&"|"&TRIM(B8) -> Barisal|Agailjhara
A9: Barisal | B9: Babuganj | C9: 190.4 | D9: 154546 | E9: 811.69 | F9: 4.01 | G9: 81.09 | H9: =TRIM(A9)&"|"&TRIM(B9) -> Barisal|Babuganj
A10: Barisal | B10: Bakerganj | C10: 259.56 | D10: 356012 | E10: 1371.6 | F10: 3.96 | G10: 79.93 | H10: =TRIM(A10)&"|"&TRIM(B10) -> Barisal|Bakerganj
A11: Barisal | B11: Banaripara | C11: 160.13 | D11: 169874 | E11: 1060.85 | F11: 4.09 | G11: 83.84 | H11: =TRIM(A11)&"|"&TRIM(B11) -> Barisal|Banaripara
A12: Barisal | B12: Gaurnadi | C12: 248.58 | D12: 205876 | E12: 828.21 | F12: 4.09 | G12: 78.25 | H12: =TRIM(A12)&"|"&TRIM(B12) -> Barisal|Gaurnadi
A13: Barisal | B13: Hizla | C13: 210.16 | D13: 150666 | E13: 716.91 | F13: 4.26 | G13: 69.83 | H13: =TRIM(A13)&"|"&TRIM(B13) -> Barisal|Hizla
... A496: Sylhet | B496: Zakiganj | C496: 517.81 | D496: 267309 | E496: 516.23 | F496: 5.28 | G496: 76.25 | H496: =TRIM(A496)&"|"&TRIM(B496) -> Sylhet|Zakiganj

Sheet Crime_Data
A1: Crime_Unit | B1: Dacoity | C1: Robbery | D1: Murder | E1: Speedy_Trial | F1: Riot | G1: Woman_Child_Repression | H1: Kidnapping | I1: Police_Assault | J1: Burglary | K1: Theft | L1: Other_Cases | M1: Arms_Act | N1: Explosive_Act | O1: Narcotics | P1: Smuggling | Q1: Recovery_Total | R1: Total_Cases | S1: Violent_Cases | T1: Property_Cases | U1: Population_2022 | V1: Total_Crime_per_100k | W1: Violent_Crime_per_100k
A2: DMP | B2: 41 | C2: 248 | D2: 339 | E2: 231 | F2: 83 | G2: 1460 | H2: 132 | I2: 95 | J2: 607 | K2: 1568 | L2: 6483 | M2: 78 | N2: 51 | O2: 6407 | P2: 141 | Q2: 6677 | R2: 17964 | S2: =B2+C2+D2+F2+G2+H2+I2 -> 2398 | T2: =B2+C2+J2+K2 -> 2464 | U2: 10295786 | V2: =IF(U2="","",R2/U2*100000) -> 174.47915 | W2: =IF(U2="","",S2/U2*100000) -> 23.291082
A3: CMP | B3: 11 | C3: 98 | D3: 90 | E3: 76 | F3: 12 | G3: 399 | H3: 40 | I3: 40 | J3: 149 | K3: 349 | L3: 1766 | M3: 31 | N3: 5 | O3: 1555 | P3: 38 | Q3: 1629 | R3: 4659 | S3: =B3+C3+D3+F3+G3+H3+I3 -> 690 | T3: =B3+C3+J3+K3 -> 607 | U3: 3230507 | V3: =IF(U3="","",R3/U3*100000) -> 144.21885 | W3: =IF(U3="","",S3/U3*100000) -> 21.358876
A4: KMP | B4: 4 | C4: 17 | D4: 24 | E4: 7 | F4: 0 | G4: 179 | H4: 11 | I4: 9 | J4: 47 | K4: 127 | L4: 477 | M4: 24 | N4: 3 | O4: 1108 | P4: 8 | Q4: 1143 | R4: 2045 | S4: =B4+C4+D4+F4+G4+H4+I4 -> 244 | T4: =B4+C4+J4+K4 -> 195 | U4: 719557 | V4: =IF(U4="","",R4/U4*100000) -> 284.20264 | W4: =IF(U4="","",S4/U4*100000) -> 33.909753
A5: RMP | B5: 2 | C5: 32 | D5: 16 | E5: 9 | F5: 1 | G5: 190 | H5: 14 | I5: 16 | J5: 44 | K5: 120 | L5: 666 | M5: 6 | N5: 45 | O5: 1215 | P5: 6 | Q5: 1272 | R5: 2382 | S5: =B5+C5+D5+F5+G5+H5+I5 -> 271 | T5: =B5+C5+J5+K5 -> 198 | U5: 553288 | V5: =IF(U5="","",R5/U5*100000) -> 430.5172 | W5: =IF(U5="","",S5/U5*100000) -> 48.979916
A6: BMP | B6: 2 | C6: 7 | D6: 15 | E6: 17 | F6: 2 | G6: 174 | H6: 8 | I6: 10 | J6: 65 | K6: 81 | L6: 687 | M6: 3 | N6: 4 | O6: 467 | P6: 3 | Q6: 477 | R6: 1545 | S6: =B6+C6+D6+F6+G6+H6+I6 -> 218 | T6: =B6+C6+J6+K6 -> 155 | U6: 419484 | V6: =IF(U6="","",R6/U6*100000) -> 368.30964 | W6: =IF(U6="","",S6/U6*100000) -> 51.968609
A7: SMP | B7: 7 | C7: 10 | D7: 24 | E7: 75 | F7: 0 | G7: 161 | H7: 11 | I7: 23 | J7: 59 | K7: 95 | L7: 723 | M7: 5 | N7: 37 | O7: 356 | P7: 168 | Q7: 566 | R7: 1754 | S7: =B7+C7+D7+F7+G7+H7+I7 -> 236 | T7: =B7+C7+J7+K7 -> 171 | U7: 532839 | V7: =IF(U7="","",R7/U7*100000) -> 329.18011 | W7: =IF(U7="","",S7/U7*100000) -> 44.291052
A8: RPMP | B8: 1 | C8: 14 | D8: 10 | E8: 5 | F8: 0 | G8: 79 | H8: 36 | I8: 2 | J8: 0 | K8: 91 | L8: 525 | M8: 5 | N8: 0 | O8: 444 | P8: 3 | Q8: 452 | R8: 1215 | S8: =B8+C8+D8+F8+G8+H8+I8 -> 142 | T8: =B8+C8+J8+K8 -> 106 | U8: 708570 | V8: =IF(U8="","",R8/U8*100000) -> 171.47212 | W8: =IF(U8="","",S8/U8*100000) -> 20.040363
A9: GMP | B9: 23 | C9: 46 | D9: 89 | E9: 13 | F9: 0 | G9: 319 | H9: 31 | I9: 22 | J9: 61 | K9: 125 | L9: 971 | M9: 10 | N9: 9 | O9: 906 | P9: 7 | Q9: 932 | R9: 2632 | S9: =B9+C9+D9+F9+G9+H9+I9 -> 530 | T9: =B9+C9+J9+K9 -> 255 | U9: 2677715 | V9: =IF(U9="","",R9/U9*100000) -> 98.292761 | W9: =IF(U9="","",S9/U9*100000) -> 19.792995
A10: Dhaka Range | B10: 178 | C10: 273 | D10: 803 | E10: 177 | F10: 2 | G10: 2928 | H10: 86 | I10: 130 | J10: 464 | K10: 1084 | L10: 12672 | M10: 136 | N10: 77 | O10: 8157 | P10: 31 | Q10: 8401 | R10: 27198 | S10: =B10+C10+D10+F10+G10+H10+I10 -> 4400 | T10: =B10+C10+J10+K10 -> 1999 | U10: 31242258 | V10: =IF(U10="","",R10/U10*100000) -> 87.055167 | W10: =IF(U10="","",S10/U10*100000) -> 14.083489
A11: Mymensingh Range | B11: 6 | C11: 42 | D11: 228 | E11: 72 | F11: 0 | G11: 1332 | H11: 32 | I11: 27 | J11: 68 | K11: 485 | L11: 5216 | M11: 28 | N11: 10 | O11: 2398 | P11: 416 | Q11: 2852 | R11: 10360 | S11: =B11+C11+D11+F11+G11+H11+I11 -> 1667 | T11: =B11+C11+J11+K11 -> 601 | U11: 12225449 | V11: =IF(U11="","",R11/U11*100000) -> 84.741264 | W11: =IF(U11="","",S11/U11*100000) -> 13.635491
A12: Chittagong Range | B12: 89 | C12: 263 | D12: 570 | E12: 112 | F12: 19 | G12: 1957 | H12: 88 | I12: 104 | J12: 419 | K12: 1169 | L12: 12186 | M12: 517 | N12: 85 | O12: 7580 | P12: 282 | Q12: 8464 | R12: 25440 | S12: =B12+C12+D12+F12+G12+H12+I12 -> 3090 | T12: =B12+C12+J12+K12 -> 1940 | U12: 29971850 | V12: =IF(U12="","",R12/U12*100000) -> 84.879645 | W12: =IF(U12="","",S12/U12*100000) -> 10.309674
A13: Sylhet Range | B13: 30 | C13: 49 | D13: 210 | E13: 59 | F13: 0 | G13: 666 | H13: 15 | I13: 40 | J13: 83 | K13: 537 | L13: 4414 | M13: 16 | N13: 5 | O13: 1185 | P13: 489 | Q13: 1695 | R13: 7798 | S13: =B13+C13+D13+F13+G13+H13+I13 -> 1010 | T13: =B13+C13+J13+K13 -> 699 | U13: 10502113 | V13: =IF(U13="","",R13/U13*100000) -> 74.251724 | W13: =IF(U13="","",S13/U13*100000) -> 9.6171123
... A17: Rangpur Range | B17: 17 | C17: 48 | D17: 230 | E17: 36 | F17: 0 | G17: 2200 | H17: 47 | I17: 23 | J17: 150 | K17: 719 | L17: 8928 | M17: 18 | N17: 4 | O17: 4731 | P17: 74 | Q17: 4827 | R17: 17225 | S17: =B17+C17+D17+F17+G17+H17+I17 -> 2565 | T17: =B17+C17+J17+K17 -> 934 | U17: 16902385 | V17: =IF(U17="","",R17/U17*100000) -> 101.9087 | W17: =IF(U17="","",S17/U17*100000) -> 15.175373
A18: Railway Range | B18: 2 | C18: 26 | D18: 12 | E18: 2 | F18: 0 | G18: 7 | H18: 0 | I18: 0 | J18: 0 | K18: 148 | L18: 221 | M18: 6 | N18: 0 | O18: 212 | P18: 7 | Q18: 225 | R18: 643 | S18: =B18+C18+D18+F18+G18+H18+I18 -> 47 | T18: =B18+C18+J18+K18 -> 176 | V18: =IF(U18="","",R18/U18*100000) | W18: =IF(U18="","",S18/U18*100000)
A19: Total | B19: 490 | C19: 1412 | D19: 3432 | E19: 1226 | F19: 125 | G19: 17571 | H19: 642 | I19: 643 | J19: 2655 | K19: 8655 | L19: 78354 | M19: 1388 | N19: 611 | O19: 52717 | P19: 2084 | Q19: 56800 | R19: 172005 | S19: =B19+C19+D19+F19+G19+H19+I19 -> 24315 | T19: =B19+C19+J19+K19 -> 13212 | U19: 165158616 | V19: =IF(U19="","",R19/U19*100000) -> 104.14534 | W19: =IF(U19="","",S19/U19*100000) -> 14.722211

Sheet District_Crime_Unit_Map
A1: District | B1: Crime_Unit
A2: Bagerhat | B2: Khulna Range
A3: Bandarban | B3: Chittagong Range
A4: Barguna | B4: Barishal Range
A5: Barishal | B5: Barishal Range
A6: Bhola | B6: Barishal Range
A7: Bogura | B7: Rajshahi Range
A8: Brahmanbaria | B8: Chittagong Range
A9: Chandpur | B9: Chittagong Range
A10: Chapainawabganj | B10: Rajshahi Range
A11: Chattogram | B11: Chittagong Range
A12: Chuadanga | B12: Khulna Range
... A83: Cox's Bazar | B83: Chittagong Range

Sheet Election_Data
A1: Constituency_ID | B1: Division | C1: Constituency | D1: Winner | E1: Party | F1: Party_binary | G1: Votes | H1: Runner_Up | I1: Runner_Party | J1: Runner_Votes | K1: Margin_Votes | L1: Margin_Percent
A2: 1 | B2: Rangpur | C2: Panchagarh-1 | D2: Muhammad Nawshad Zamir | E2: BNP | F2: =IF(E2="Jamaat",1,0) -> 0 | G2: 176169 | H2: Sarjis Alam | I2: NCP | J2: 168049 | K2: 8120
A3: 2 | C3: Panchagarh-2 | D3: Farhad Hossain Azad | E3: BNP | F3: =IF(E3="Jamaat",1,0) -> 0 | G3: 174650 | H3: Md. Shafiul Alam | I3: Jamaat | J3: 128862 | K3: 45788
A4: 3 | C4: Thakurgaon-1 | D4: Mirza Fakhrul Islam Alamgir | E4: BNP | F4: =IF(E4="Jamaat",1,0) -> 0 | G4: 238836 | H4: Delawar Hossain | I4: Jamaat | J4: 141017 | K4: 97819
A5: 4 | C5: Thakurgaon-2 | D5: Abdus Salam | E5: BNP | F5: =IF(E5="Jamaat",1,0) -> 0 | G5: 121017 | H5: Md. Abdul Hakim | I5: Jamaat | J5: 115707 | K5: 5310
A6: 5 | C6: Thakurgaon-3 | D6: Jahidur Rahman | E6: BNP | F6: =IF(E6="Jamaat",1,0) -> 0 | G6: 132797 | H6: Md. Mizanur Rahman | I6: Jamaat | J6: 91934 | K6: 40863
A7: 6 | C7: Dinajpur-1 | D7: Md. Manjurul Islam | E7: BNP | F7: =IF(E7="Jamaat",1,0) -> 0 | G7: 179314 | H7: Md. Matiur Rahman | I7: Jamaat | J7: 117481 | K7: 61833
A8: 7 | C8: Dinajpur-2 | D8: Md. Sadiq Riaz | E8: BNP | F8: =IF(E8="Jamaat",1,0) -> 0 | G8: 144317 | H8: A. K. M. Afzalul Anam | I8: Jamaat | J8: 101831 | K8: 42486
A9: 8 | C9: Dinajpur-3 | D9: Syed Jahangir Alam | E9: BNP | F9: =IF(E9="Jamaat",1,0) -> 0 | G9: 139207 | H9: Md. Mainul Alam | I9: Jamaat | J9: 134618 | K9: 4589
A10: 9 | C10: Dinajpur-4 | D10: Md. Akhtaruzzaman Mia | E10: BNP | F10: =IF(E10="Jamaat",1,0) -> 0 | G10: 165577 | H10: Md. Aftab Uddin Mollah | I10: Jamaat | J10: 127666 | K10: 37911
A11: 10 | C11: Dinajpur-5 | D11: A. Z. M. Rezwanul Haque | E11: IND | F11: =IF(E11="Jamaat",1,0) -> 0 | G11: 113650 | H11: Md. Abdul Ahad | I11: NCP | J11: 108948 | K11: 4702
A12: 11 | C12: Dinajpur-6 | D12: A. Z. M. Zahid Hossain | E12: BNP | F12: =IF(E12="Jamaat",1,0) -> 0 | G12: 203887 | H12: Md. Anwarul Islam | I12: Jamaat | J12: 188719 | K12: 15168
A13: 12 | C13: Nilphamari-1 | D13: Md. Abdus Sattar | E13: Jamaat | F13: =IF(E13="Jamaat",1,0) -> 1 | G13: 149224 | H13: Md. Manjurul Islam | I13: JUIB | J13: 118160 | K13: 31064
A14: 13 | C14: Nilphamari-2 | D14: Alfaruk Abdul Latif | E14: Jamaat | F14: =IF(E14="Jamaat",1,0) -> 1 | G14: 145202 | H14: Shahrin Islam Tuhin | I14: BNP | J14: 134579 | K14: 10623
... A34: 33 | C34: Gaibandha-5 | D34: Md. Abdul Warres | E34: Jamaat | F34: =IF(E34="Jamaat",1,0) -> 1 | G34: 89274 | H34: Md. Farooq Alam Sarkar | I34: BNP | J34: 73483 | K34: 15791
A35: 34 | B35: Rajshahi | C35: Joypurhat-1 | D35: Md. Fazlur Rahman Sayeed | E35: Jamaat | F35: =IF(E35="Jamaat",1,0) -> 1 | G35: 165192 | H35: Md. Masud Rana Pradhan | I35: BNP | J35: 155309 | K35: 9883
A36: 35 | C36: Joypurhat-2 | D36: Md. Abdul Bari | E36: BNP | F36: =IF(E36="Jamaat",1,0) -> 0 | G36: 158065 | H36: SM Rashedul Alam | I36: Jamaat | J36: 92517 | K36: 65548
A37: 36 | C37: Bogra-1 | D37: Kazi Rafiqul Islam | E37: BNP | F37: =IF(E37="Jamaat",1,0) -> 0 | G37: 171440 | H37: Md. Shahabuddin | I37: Jamaat | J37: 57959 | K37: 113481
A38: 37 | C38: Bogra-2 | D38: Mir Shahe Alam | E38: BNP | F38: =IF(E38="Jamaat",1,0) -> 0 | G38: 145024 | H38: Abul Azad Md Shahaduzzaman | I38: Jamaat | J38: 93548 | K38: 51476
A39: 38 | C39: Bogra-3 | D39: Md. Abdul Mohit Talukder | E39: BNP | F39: =IF(E39="Jamaat",1,0) -> 0 | G39: 127406 | H39: Noor Mohammad | I39: Jamaat | J39: 111026 | K39: 16380
A40: 39 | C40: Bogra-4 | D40: Md. Mosharraf Hossain | E40: BNP | F40: =IF(E40="Jamaat",1,0) -> 0 | G40: 155339 | H40: Md. Mustafa Faisal | I40: Jamaat | J40: 108978 | K40: 46361
A41: 40 | C41: Bogra-5 | D41: Gholam Mohammad Siraj | E41: BNP | F41: =IF(E41="Jamaat",1,0) -> 0 | G41: 248841 | H41: Md. Dabibur Rahman | I41: Jamaat | J41: 143329 | K41: 105512
A42: 41 | C42: Bogra-6 | D42: Tarique Rahman | E42: BNP | F42: =IF(E42="Jamaat",1,0) -> 0 | G42: 216284 | H42: Md. Abidur Rahman | I42: Jamaat | J42: 97626 | K42: 118658
A43: 42 | C43: Bogra-7 | D43: Morshed Milton | E43: BNP | F43: =IF(E43="Jamaat",1,0) -> 0 | G43: 264212 | H43: Md. Golam Rabbani | I43: Jamaat | J43: 116665 | K43: 147547
A44: 43 | C44: Chapai Nawabganj-1 | D44: Md. Keramat Ali | E44: Jamaat | F44: =IF(E44="Jamaat",1,0) -> 1 | G44: 206893 | H44: Md. Shahjahan Mia | I44: BNP | J44: 162515 | K44: 44378
A45: 44 | C45: Chapai Nawabganj-2 | D45: Md. Mizanur Rahman | E45: Jamaat | F45: =IF(E45="Jamaat",1,0) -> 1 | G45: 171227 | H45: Md. Aminul Islam | I45: BNP | J45: 155119 | K45: 16108
A46: 45 | C46: Chapai Nawabganj-3 | D46: Md. Nurul Islam | E46: Jamaat | F46: =IF(E46="Jamaat",1,0) -> 1 | G46: 189640 | H46: Harunur Rashid | I46: BNP | J46: 127037 | K46: 62603
A47: 46 | C47: Naogaon-1 | D47: Md. Mostafizur Rahman | E47: BNP | F47: =IF(E47="Jamaat",1,0) -> 0 | G47: 173864 | H47: Md. Mahbubul Alam | I47: Jamaat | J47: 153816 | K47: 20048
... A73: 72 | C73: Pabna-5 | D73: Shamsur Rahman Simul Biswas | E73: BNP | F73: =IF(E73="Jamaat",1,0) -> 0 | G73: 181925 | H73: Md. Iqbal Hossain | I73: Jamaat | J73: 164994 | K73: 16931
A74: 73 | B74: Khulna | C74: Meherpur-1 | D74: Md. Tajuddin Khan | E74: Jamaat | F74: =IF(E74="Jamaat",1,0) -> 1 | G74: 123271 | H74: Masood Arun | I74: BNP | J74: 105441 | K74: 17830
A75: 74 | C75: Meherpur-2 | D75: Md. Nazmul Huda | E75: Jamaat | F75: =IF(E75="Jamaat",1,0) -> 1 | G75: 96306 | H75: Md. Amjad Hossain | I75: BNP | J75: 85988 | K75: 10318
A76: 75 | C76: Kushtia-1 | D76: Reza Ahmed | E76: BNP | F76: =IF(E76="Jamaat",1,0) -> 0 | G76: 165909 | H76: Md. Belal Uddin | I76: Jamaat | J76: 86682 | K76: 79227
A77: 76 | C77: Kushtia-2 | D77: Abdul Ghafoor | E77: Jamaat | F77: =IF(E77="Jamaat",1,0) -> 1 | G77: 192083 | H77: Ragib Rauf Chowdhury | I77: BNP | J77: 143821 | K77: 48262
A78: 77 | C78: Kushtia-3 | D78: Amir Hamza | E78: Jamaat | F78: =IF(E78="Jamaat",1,0) -> 1 | G78: 180690 | H78: Md. Zakir Hossain Sarkar | I78: BNP | J78: 126909 | K78: 53781
A79: 78 | C79: Kushtia-4 | D79: Md. Afjal Hossain | E79: Jamaat | F79: =IF(E79="Jamaat",1,0) -> 1 | G79: 148201 | H79: Syed Mehdi Ahmed Rumi | I79: BNP | J79: 139603 | K79: 8598
A80: 79 | C80: Chuadanga-1 | D80: Md. Masood Parvez | E80: Jamaat | F80: =IF(E80="Jamaat",1,0) -> 1 | G80: 211041 | H80: Md. Sharifuzzaman | I80: BNP | J80: 153193 | K80: 57848
A81: 80 | C81: Chuadanga-2 | D81: Md. Ruhul Amin | E81: Jamaat | F81: =IF(E81="Jamaat",1,0) -> 1 | G81: 208011 | H81: Mahmud Hasan Khan | I81: BNP | J81: 163877 | K81: 44134
A82: 81 | C82: Jhenaidah-1 | D82: Md. Asaduzzaman | E82: BNP | F82: =IF(E82="Jamaat",1,0) -> 0 | G82: 173381 | H82: Abu Saleh Md. Matiur Rahman | I82: Jamaat | J82: 57055 | K82: 116326
A83: 82 | C83: Jhenaidah-2 | D83: Ali Azam Md. Abu Bakr | E83: Jamaat | F83: =IF(E83="Jamaat",1,0) -> 1 | G83: 195702 | H83: Md. Abdul Majeed | I83: BNP | J83: 175984 | K83: 19718
A84: 83 | C84: Jhenaidah-3 | D84: Md. Motiyar Rahman | E84: Jamaat | F84: =IF(E84="Jamaat",1,0) -> 1 | G84: 175857 | H84: Mohammad Mehdi Hasan | I84: BNP | J84: 149821 | K84: 26036
...

Sheet Final_Merged_Data
A1: Constituency | B1: Constituency_Clean | C1: Upazila | D1: District | E1: Area_sqkm | F1: Population | G1: Population_Density | H1: Household_Size | I1: Literacy_Rate | J1: Crime_Unit | K1: Total_Crime_per_100k | L1: Violent_Crime_per_100k | M1: Merge_Key | N1: Remittance_HH_Total | O1: Remittance_HH_Rural | P1: Remittance_HH_Urban
A2: Panchagarh-1 | B2: =SUBSTITUTE(SUBSTITUTE(SUBSTITUTE(SUBSTITUTE(TRIM(Table6[[#This Row],[Constituency]]),"Barisal","Barishal"),"Jessore","Jashore"),"Bogra","Bogura"),"Chapai Nawabganj","Chapainawabganj") -> Panchagarh-1 | C2: Panchagarh Sadar | D2: Panchagarh | E2: =_xlfn.XLOOKUP(C2,Population_data!B:B,Population_data!C:C,"") -> 189.12 | F2: =_xlfn.XLOOKUP(C2,Population_data!B:B,Population_data!D:D,"") -> 335353 | G2: =_xlfn.XLOOKUP(C2,Population_data!B:B,Population_data!E:E,"") -> 1773.23 | H2: =_xlfn.XLOOKUP(C2,Population_data!B:B,Population_data!F:F,"") -> 4.25 | I2: =_xlfn.XLOOKUP(C2,Population_data!B:B,Population_data!G:G,"") -> 75.59 | J2: =_xlfn.XLOOKUP(D2,District_Crime_Unit_Map!A:A,District_Crime_Unit_Map!B:B,"") -> Rangpur Range | K2: =_xlfn.XLOOKUP(J2,Crime_Data!A:A,Crime_Data!V:V,"") -> 101.9087 | L2: =_xlfn.XLOOKUP(J2,Crime_Data!A:A,Crime_Data!W:W,"") -> 15.175373 | M2: =TRIM(Table6[[#This Row],[District]])&"|"&TRIM(Table6[[#This Row],[Upazila]]) -> Panchagarh|Panchagarh Sadar | N2: =_xlfn.XLOOKUP(B2,Remittance_Data!A:A,Remittance_Data!B:B,"CHECK") -> CHECK | O2: =_xlfn.XLOOKUP(B2,Remittance_Data!A:A,Remittance_Data!C:C,"CHECK") -> CHECK | P2: =_xlfn.XLOOKUP(B2,Remittance_Data!A:A,Remittance_Data!D:D,"CHECK") -> CHECK
A3: Panchagarh-1 | B3: =SUBSTITUTE(SUBSTITUTE(SUBSTITUTE(SUBSTITUTE(TRIM(Table6[[#This Row],[Constituency]]),"Barisal","Barishal"),"Jessore","Jashore"),"Bogra","Bogura"),"Chapai Nawabganj","Chapainawabganj") -> Panchagarh-1 | C3: Tetulia | D3: Panchagarh | E3: =_xlfn.XLOOKUP(C3,Population_data!B:B,Population_data!C:C,"") -> 303.5 | F3: =_xlfn.XLOOKUP(C3,Population_data!B:B,Population_data!D:D,"") -> 160178 | G3: =_xlfn.XLOOKUP(C3,Population_data!B:B,Population_data!E:E,"") -> 527.77 | H3: =_xlfn.XLOOKUP(C3,Population_data!B:B,Population_data!F:F,"") -> 4.33 | I3: =_xlfn.XLOOKUP(C3,Population_data!B:B,Population_data!G:G,"") -> 71.78 | J3: =_xlfn.XLOOKUP(D3,District_Crime_Unit_Map!A:A,District_Crime_Unit_Map!B:B,"") -> Rangpur Range | K3: =_xlfn.XLOOKUP(J3,Crime_Data!A:A,Crime_Data!V:V,"") -> 101.9087 | L3: =_xlfn.XLOOKUP(J3,Crime_Data!A:A,Crime_Data!W:W,"") -> 15.175373 | M3: =TRIM(Table6[[#This Row],[District]])&"|"&TRIM(Table6[[#This Row],[Upazila]]) -> Panchagarh|Tetulia | N3: =_xlfn.XLOOKUP(B3,Remittance_Data!A:A,Remittance_Data!B:B,"CHECK") -> CHECK | O3: =_xlfn.XLOOKUP(B3,Remittance_Data!A:A,Remittance_Data!C:C,"CHECK") -> CHECK | P3: =_xlfn.XLOOKUP(B3,Remittance_Data!A:A,Remittance_Data!D:D,"CHECK") -> CHECK
A4: Panchagarh-1 | B4: =SUBSTITUTE(SUBSTITUTE(SUBSTITUTE(SUBSTITUTE(TRIM(Table6[[#This Row],[Constituency]]),"Barisal","Barishal"),"Jessore","Jashore"),"Bogra","Bogura"),"Chapai Nawabganj","Chapainawabganj") -> Panchagarh-1 | C4: Atwari | D4: Panchagarh | E4: =_xlfn.XLOOKUP(C4,Population_data!B:B,Population_data!C:C,"") -> 286.81 | F4: =_xlfn.XLOOKUP(C4,Population_data!B:B,Population_data!D:D,"") -> 141545 | G4: =_xlfn.XLOOKUP(C4,Population_data!B:B,Population_data!E:E,"") -> 493.51 | H4: =_xlfn.XLOOKUP(C4,Population_data!B:B,Population_data!F:F,"") -> 3.97 | I4: =_xlfn.XLOOKUP(C4,Population_data!B:B,Population_data!G:G,"") -> 76.19 | J4: =_xlfn.XLOOKUP(D4,District_Crime_Unit_Map!A:A,District_Crime_Unit_Map!B:B,"") -> Rangpur Range | K4: =_xlfn.XLOOKUP(J4,Crime_Data!A:A,Crime_Data!V:V,"") -> 101.9087 | L4: =_xlfn.XLOOKUP(J4,Crime_Data!A:A,Crime_Data!W:W,"") -> 15.175373 | M4: =TRIM(Table6[[#This Row],[District]])&"|"&TRIM(Table6[[#This Row],[Upazila]]) -> Panchagarh|Atwari | N4: =_xlfn.XLOOKUP(B4,Remittance_Data!A:A,Remittance_Data!B:B,"CHECK") -> CHECK | O4: =_xlfn.XLOOKUP(B4,Remittance_Data!A:A,Remittance_Data!C:C,"CHECK") -> CHECK | P4: =_xlfn.XLOOKUP(B4,Remittance_Data!A:A,Remittance_Data!D:D,"CHECK") -> CHECK
A5: Panchagarh-2 | B5: =SUBSTITUTE(SUBSTITUTE(SUBSTITUTE(SUBSTITUTE(TRIM(Table6[[#This Row],[Constituency]]),"Barisal","Barishal"),"Jessore","Jashore"),"Bogra","Bogura"),"Chapai Nawabganj","Chapainawabganj") -> Panchagarh-2 | C5: Boda | D5: Panchagarh | E5: =_xlfn.XLOOKUP(C5,Population_data!B:B,Population_data!C:C,"") -> 189.29 | F5: =_xlfn.XLOOKUP(C5,Population_data!B:B,Population_data!D:D,"") -> 275279 | G5: =_xlfn.XLOOKUP(C5,Population_data!B:B,Population_data!E:E,"") -> 1454.27 | H5: =_xlfn.XLOOKUP(C5,Population_data!B:B,Population_data!F:F,"") -> 4.05 | I5: =_xlfn.XLOOKUP(C5,Population_data!B:B,Population_data!G:G,"") -> 73.67 | J5: =_xlfn.XLOOKUP(D5,District_Crime_Unit_Map!A:A,District_Crime_Unit_Map!B:B,"") -> Rangpur Range | K5: =_xlfn.XLOOKUP(J5,Crime_Data!A:A,Crime_Data!V:V,"") -> 101.9087 | L5: =_xlfn.XLOOKUP(J5,Crime_Data!A:A,Crime_Data!W:W,"") -> 15.175373 | M5: =TRIM(Table6[[#This Row],[District]])&"|"&TRIM(Table6[[#This Row],[Upazila]]) -> Panchagarh|Boda | N5: =_xlfn.XLOOKUP(B5,Remittance_Data!A:A,Remittance_Data!B:B,"CHECK") -> CHECK | O5: =_xlfn.XLOOKUP(B5,Remittance_Data!A:A,Remittance_Data!C:C,"CHECK") -> CHECK | P5: =_xlfn.XLOOKUP(B5,Remittance_Data!A:A,Remittance_Data!D:D,"CHECK") -> CHECK
A6: Panchagarh-2 | B6: =SUBSTITUTE(SUBSTITUTE(SUBSTITUTE(SUBSTITUTE(TRIM(Table6[[#This Row],[Constituency]]),"Barisal","Barishal"),"Jessore","Jashore"),"Bogra","Bogura"),"Chapai Nawabganj","Chapainawabganj") -> Panchagarh-2 | C6: Debiganj | D6: Panchagarh | E6: =_xlfn.XLOOKUP(C6,Population_data!B:B,Population_data!C:C,"") -> 359.52 | F6: =_xlfn.XLOOKUP(C6,Population_data!B:B,Population_data!D:D,"") -> 267452 | G6: =_xlfn.XLOOKUP(C6,Population_data!B:B,Population_data!E:E,"") -> 743.91 | H6: =_xlfn.XLOOKUP(C6,Population_data!B:B,Population_data!F:F,"") -> 4.1 | I6: =_xlfn.XLOOKUP(C6,Population_data!B:B,Population_data!G:G,"") -> 71.04 | J6: =_xlfn.XLOOKUP(D6,District_Crime_Unit_Map!A:A,District_Crime_Unit_Map!B:B,"") -> Rangpur Range | K6: =_xlfn.XLOOKUP(J6,Crime_Data!A:A,Crime_Data!V:V,"") -> 101.9087 | L6: =_xlfn.XLOOKUP(J6,Crime_Data!A:A,Crime_Data!W:W,"") -> 15.175373 | M6: =TRIM(Table6[[#This Row],[District]])&"|"&TRIM(Table6[[#This Row],[Upazila]]) -> Panchagarh|Debiganj | N6: =_xlfn.XLOOKUP(B6,Remittance_Data!A:A,Remittance_Data!B:B,"CHECK") -> CHECK | O6: =_xlfn.XLOOKUP(B6,Remittance_Data!A:A,Remittance_Data!C:C,"CHECK") -> CHECK | P6: =_xlfn.XLOOKUP(B6,Remittance_Data!A:A,Remittance_Data!D:D,"CHECK") -> CHECK
A7: Thakurgaon-1 | B7: =SUBSTITUTE(SUBSTITUTE(SUBSTITUTE(SUBSTITUTE(TRIM(Table6[[#This Row],[Constituency]]),"Barisal","Barishal"),"Jessore","Jashore"),"Bogra","Bogura"),"Chapai Nawabganj","Chapainawabganj") -> Thakurgaon-1 | C7: Thakurgaon Sadar | D7: Thakurgaon | E7: =_xlfn.XLOOKUP(C7,Population_data!B:B,Population_data!C:C,"") -> 172.65 | F7: =_xlfn.XLOOKUP(C7,Population_data!B:B,Population_data!D:D,"") -> 656770 | G7: =_xlfn.XLOOKUP(C7,Population_data!B:B,Population_data!E:E,"") -> 3804.05 | H7: =_xlfn.XLOOKUP(C7,Population_data!B:B,Population_data!F:F,"") -> 3.99 | I7: =_xlfn.XLOOKUP(C7,Population_data!B:B,Population_data!G:G,"") -> 76.85 | J7: =_xlfn.XLOOKUP(D7,District_Crime_Unit_Map!A:A,District_Crime_Unit_Map!B:B,"") -> Rangpur Range | K7: =_xlfn.XLOOKUP(J7,Crime_Data!A:A,Crime_Data!V:V,"") -> 101.9087 | L7: =_xlfn.XLOOKUP(J7,Crime_Data!A:A,Crime_Data!W:W,"") -> 15.175373 | M7: =TRIM(Table6[[#This Row],[District]])&"|"&TRIM(Table6[[#This Row],[Upazila]]) -> Thakurgaon|Thakurgaon Sadar | N7: =_xlfn.XLOOKUP(B7,Remittance_Data!A:A,Remittance_Data!B:B,"CHECK") -> CHECK | O7: =_xlfn.XLOOKUP(B7,Remittance_Data!A:A,Remittance_Data!C:C,"CHECK") -> CHECK | P7: =_xlfn.XLOOKUP(B7,Remittance_Data!A:A,Remittance_Data!D:D,"CHECK") -> CHECK
A8: Thakurgaon-2 | B8: =SUBSTITUTE(SUBSTITUTE(SUBSTITUTE(SUBSTITUTE(TRIM(Table6[[#This Row],[Constituency]]),"Barisal","Barishal"),"Jessore","Jashore"),"Bogra","Bogura"),"Chapai Nawabganj","Chapainawabganj") -> Thakurgaon-2 | C8: Baliadangi | D8: Thakurgaon | E8: =_xlfn.XLOOKUP(C8,Population_data!B:B,Population_data!C:C,"") -> 258.61 | F8: =_xlfn.XLOOKUP(C8,Population_data!B:B,Population_data!D:D,"") -> 208346 | G8: =_xlfn.XLOOKUP(C8,Population_data!B:B,Population_data!E:E,"") -> 805.64 | H8: =_xlfn.XLOOKUP(C8,Population_data!B:B,Population_data!F:F,"") -> 3.94 | I8: =_xlfn.XLOOKUP(C8,Population_data!B:B,Population_data!G:G,"") -> 70.95 | J8: =_xlfn.XLOOKUP(D8,District_Crime_Unit_Map!A:A,District_Crime_Unit_Map!B:B,"") -> Rangpur Range | K8: =_xlfn.XLOOKUP(J8,Crime_Data!A:A,Crime_Data!V:V,"") -> 101.9087 | L8: =_xlfn.XLOOKUP(J8,Crime_Data!A:A,Crime_Data!W:W,"") -> 15.175373 | M8: =TRIM(Table6[[#This Row],[District]])&"|"&TRIM(Table6[[#This Row],[Upazila]]) -> Thakurgaon|Baliadangi | N8: =_xlfn.XLOOKUP(B8,Remittance_Data!A:A,Remittance_Data!B:B,"CHECK") -> CHECK | O8: =_xlfn.XLOOKUP(B8,Remittance_Data!A:A,Remittance_Data!C:C,"CHECK") -> CHECK | P8: =_xlfn.XLOOKUP(B8,Remittance_Data!A:A,Remittance_Data!D:D,"CHECK") -> CHECK
A9: Thakurgaon-2 | B9: =SUBSTITUTE(SUBSTITUTE(SUBSTITUTE(SUBSTITUTE(TRIM(Table6[[#This Row],[Constituency]]),"Barisal","Barishal"),"Jessore","Jashore"),"Bogra","Bogura"),"Chapai Nawabganj","Chapainawabganj") -> Thakurgaon-2 | C9: Haripur | D9: Thakurgaon | E9: =_xlfn.XLOOKUP(C9,Population_data!B:B,Population_data!C:C,"") -> 258.03 | F9: =_xlfn.XLOOKUP(C9,Population_data!B:B,Population_data!D:D,"") -> 159510 | G9: =_xlfn.XLOOKUP(C9,Population_data!B:B,Population_data!E:E,"") -> 618.18 | H9: =_xlfn.XLOOKUP(C9,Population_data!B:B,Population_data!F:F,"") -> 4.05 | I9: =_xlfn.XLOOKUP(C9,Population_data!B:B,Population_data!G:G,"") -> 68.98 | J9: =_xlfn.XLOOKUP(D9,District_Crime_Unit_Map!A:A,District_Crime_Unit_Map!B:B,"") -> Rangpur Range | K9: =_xlfn.XLOOKUP(J9,Crime_Data!A:A,Crime_Data!V:V,"") -> 101.9087 | L9: =_xlfn.XLOOKUP(J9,Crime_Data!A:A,Crime_Data!W:W,"") -> 15.175373 | M9: =TRIM(Table6[[#This Row],[District]])&"|"&TRIM(Table6[[#This Row],[Upazila]]) -> Thakurgaon|Haripur | N9: =_xlfn.XLOOKUP(B9,Remittance_Data!A:A,Remittance_Data!B:B,"CHECK") -> CHECK | O9: =_xlfn.XLOOKUP(B9,Remittance_Data!A:A,Remittance_Data!C:C,"CHECK") -> CHECK | P9: =_xlfn.XLOOKUP(B9,Remittance_Data!A:A,Remittance_Data!D:D,"CHECK") -> CHECK
A10: Thakurgaon-2 | B10: =SUBSTITUTE(SUBSTITUTE(SUBSTITUTE(SUBSTITUTE(TRIM(Table6[[#This Row],[Constituency]]),"Barisal","Barishal"),"Jessore","Jashore"),"Bogra","Bogura"),"Chapai Nawabganj","Chapainawabganj") -> Thakurgaon-2 | C10: Ranishankail | D10: Thakurgaon | E10: =_xlfn.XLOOKUP(C10,Population_data!B:B,Population_data!C:C,"") -> 334.67 | F10: =_xlfn.XLOOKUP(C10,Population_data!B:B,Population_data!D:D,"") -> 244074 | G10: =_xlfn.XLOOKUP(C10,Population_data!B:B,Population_data!E:E,"") -> 729.3 | H10: =_xlfn.XLOOKUP(C10,Population_data!B:B,Population_data!F:F,"") -> 3.92 | I10: =_xlfn.XLOOKUP(C10,Population_data!B:B,Population_data!G:G,"") -> 73.7 | J10: =_xlfn.XLOOKUP(D10,District_Crime_Unit_Map!A:A,District_Crime_Unit_Map!B:B,"") -> Rangpur Range | K10: =_xlfn.XLOOKUP(J10,Crime_Data!A:A,Crime_Data!V:V,"") -> 101.9087 | L10: =_xlfn.XLOOKUP(J10,Crime_Data!A:A,Crime_Data!W:W,"") -> 15.175373 | M10: =TRIM(Table6[[#This Row],[District]])&"|"&TRIM(Table6[[#This Row],[Upazila]]) -> Thakurgaon|Ranishankail | N10: =_xlfn.XLOOKUP(B10,Remittance_Data!A:A,Remittance_Data!B:B,"CHECK") -> CHECK | O10: =_xlfn.XLOOKUP(B10,Remittance_Data!A:A,Remittance_Data!C:C,"CHECK") -> CHECK | P10: =_xlfn.XLOOKUP(B10,Remittance_Data!A:A,Remittance_Data!D:D,"CHECK") -> CHECK
A11: Thakurgaon-3 | B11: =SUBSTITUTE(SUBSTITUTE(SUBSTITUTE(SUBSTITUTE(TRIM(Table6[[#This Row],[Constituency]]),"Barisal","Barishal"),"Jessore","Jashore"),"Bogra","Bogura"),"Chapai Nawabganj","Chapainawabganj") -> Thakurgaon-3 | C11: Pirganj | D11: Thakurgaon | E11: =_xlfn.XLOOKUP(C11,Population_data!B:B,Population_data!C:C,"") -> 280.43 | F11: =_xlfn.XLOOKUP(C11,Population_data!B:B,Population_data!D:D,"") -> 414833 | G11: =_xlfn.XLOOKUP(C11,Population_data!B:B,Population_data!E:E,"") -> 1479.27 | H11: =_xlfn.XLOOKUP(C11,Population_data!B:B,Population_data!F:F,"") -> 3.58 | I11: =_xlfn.XLOOKUP(C11,Population_data!B:B,Population_data!G:G,"") -> 67.11 | J11: =_xlfn.XLOOKUP(D11,District_Crime_Unit_Map!A:A,District_Crime_Unit_Map!B:B,"") -> Rangpur Range | K11: =_xlfn.XLOOKUP(J11,Crime_Data!A:A,Crime_Data!V:V,"") -> 101.9087 | L11: =_xlfn.XLOOKUP(J11,Crime_Data!A:A,Crime_Data!W:W,"") -> 15.175373 | M11: =TRIM(Table6[[#This Row],[District]])&"|"&TRIM(Table6[[#This Row],[Upazila]]) -> Thakurgaon|Pirganj | N11: =_xlfn.XLOOKUP(B11,Remittance_Data!A:A,Remittance_Data!B:B,"CHECK") -> CHECK | O11: =_xlfn.XLOOKUP(B11,Remittance_Data!A:A,Remittance_Data!C:C,"CHECK") -> CHECK | P11: =_xlfn.XLOOKUP(B11,Remittance_Data!A:A,Remittance_Data!D:D,"CHECK") -> CHECK
A12: Thakurgaon-3 | B12: =SUBSTITUTE(SUBSTITUTE(SUBSTITUTE(SUBSTITUTE(TRIM(Table6[[#This Row],[Constituency]]),"Barisal","Barishal"),"Jessore","Jashore"),"Bogra","Bogura"),"Chapai Nawabganj","Chapainawabganj") -> Thakurgaon-3 | C12: Ranishankail | D12: Thakurgaon | E12: =_xlfn.XLOOKUP(C12,Population_data!B:B,Population_data!C:C,"") -> 334.67 | F12: =_xlfn.XLOOKUP(C12,Population_data!B:B,Population_data!D:D,"") -> 244074 | G12: =_xlfn.XLOOKUP(C12,Population_data!B:B,Population_data!E:E,"") -> 729.3 | H12: =_xlfn.XLOOKUP(C12,Population_data!B:B,Population_data!F:F,"") -> 3.92 | I12: =_xlfn.XLOOKUP(C12,Population_data!B:B,Population_data!G:G,"") -> 73.7 | J12: =_xlfn.XLOOKUP(D12,District_Crime_Unit_Map!A:A,District_Crime_Unit_Map!B:B,"") -> Rangpur Range | K12: =_xlfn.XLOOKUP(J12,Crime_Data!A:A,Crime_Data!V:V,"") -> 101.9087 | L12: =_xlfn.XLOOKUP(J12,Crime_Data!A:A,Crime_Data!W:W,"") -> 15.175373 | M12: =TRIM(Table6[[#This Row],[District]])&"|"&TRIM(Table6[[#This Row],[Upazila]]) -> Thakurgaon|Ranishankail | N12: =_xlfn.XLOOKUP(B12,Remittance_Data!A:A,Remittance_Data!B:B,"CHECK") -> CHECK | O12: =_xlfn.XLOOKUP(B12,Remittance_Data!A:A,Remittance_Data!C:C,"CHECK") -> CHECK | P12: =_xlfn.XLOOKUP(B12,Remittance_Data!A:A,Remittance_Data!D:D,"CHECK") -> CHECK
A13: Dinajpur-1 | B13: =SUBSTITUTE(SUBSTITUTE(SUBSTITUTE(SUBSTITUTE(TRIM(Table6[[#This Row],[Constituency]]),"Barisal","Barishal"),"Jessore","Jashore"),"Bogra","Bogura"),"Chapai Nawabganj","Chapainawabganj") -> Dinajpur-1 | C13: Birganj | D13: Dinajpur | E13: =_xlfn.XLOOKUP(C13,Population_data!B:B,Population_data!C:C,"") -> 193.61 | F13: =_xlfn.XLOOKUP(C13,Population_data!B:B,Population_data!D:D,"") -> 356140 | G13: =_xlfn.XLOOKUP(C13,Population_data!B:B,Population_data!E:E,"") -> 1839.47 | H13: =_xlfn.XLOOKUP(C13,Population_data!B:B,Population_data!F:F,"") -> 4 | I13: =_xlfn.XLOOKUP(C13,Population_data!B:B,Population_data!G:G,"") -> 73.21 | J13: =_xlfn.XLOOKUP(D13,District_Crime_Unit_Map!A:A,District_Crime_Unit_Map!B:B,"") -> Rangpur Range | K13: =_xlfn.XLOOKUP(J13,Crime_Data!A:A,Crime_Data!V:V,"") -> 101.9087 | L13: =_xlfn.XLOOKUP(J13,Crime_Data!A:A,Crime_Data!W:W,"") -> 15.175373 | M13: =TRIM(Table6[[#This Row],[District]])&"|"&TRIM(Table6[[#This Row],[Upazila]]) -> Dinajpur|Birganj | N13: =_xlfn.XLOOKUP(B13,Remittance_Data!A:A,Remittance_Data!B:B,"CHECK") -> CHECK | O13: =_xlfn.XLOOKUP(B13,Remittance_Data!A:A,Remittance_Data!C:C,"CHECK") -> CHECK | P13: =_xlfn.XLOOKUP(B13,Remittance_Data!A:A,Remittance_Data!D:D,"CHECK") -> CHECK
... A96: Rajshahi-1 | B96: =SUBSTITUTE(SUBSTITUTE(SUBSTITUTE(SUBSTITUTE(TRIM(Table6[[#This Row],[Constituency]]),"Barisal","Barishal"),"Jessore","Jashore"),"Bogra","Bogura"),"Chapai Nawabganj","Chapainawabganj") -> Rajshahi-1 | C96: Tanor | D96: Rajshahi | E96: =_xlfn.XLOOKUP(C96,Population_data!B:B,Population_data!C:C,"") -> 280.42 | F96: =_xlfn.XLOOKUP(C96,Population_data!B:B,Population_data!D:D,"") -> 212968 | G96: =_xlfn.XLOOKUP(C96,Population_data!B:B,Population_data!E:E,"") -> 759.46 | H96: =_xlfn.XLOOKUP(C96,Population_data!B:B,Population_data!F:F,"") -> 3.61 | I96: =_xlfn.XLOOKUP(C96,Population_data!B:B,Population_data!G:G,"") -> 72.31 | J96: =_xlfn.XLOOKUP(D96,District_Crime_Unit_Map!A:A,District_Crime_Unit_Map!B:B,"") -> Rajshahi Range | K96: =_xlfn.XLOOKUP(J96,Crime_Data!A:A,Crime_Data!V:V,"") -> 112.81411 | L96: =_xlfn.XLOOKUP(J96,Crime_Data!A:A,Crime_Data!W:W,"") -> 14.272851 | M96: =TRIM(Table6[[#This Row],[District]])&"|"&TRIM(Table6[[#This Row],[Upazila]]) -> Rajshahi|Tanor | N96: =_xlfn.XLOOKUP(B96,Remittance_Data!A:A,Remittance_Data!B:B,"CHECK") -> CHECK | O96: =_xlfn.XLOOKUP(B96,Remittance_Data!A:A,Remittance_Data!C:C,"CHECK") -> CHECK | P96: =_xlfn.XLOOKUP(B96,Remittance_Data!A:A,Remittance_Data!D:D,"CHECK") -> CHECK
A97: Rajshahi-2 | B97: =SUBSTITUTE(SUBSTITUTE(SUBSTITUTE(SUBSTITUTE(TRIM(Table6[[#This Row],[Constituency]]),"Barisal","Barishal"),"Jessore","Jashore"),"Bogra","Bogura"),"Chapai Nawabganj","Chapainawabganj") -> Rajshahi-2 | C97: Rajshahi City Corporation | D97: Rajshahi | E97: 96.72 | F97: 550599 | G97: 5693 | H97: 3.75 | I97: 88.83 | J97: =_xlfn.XLOOKUP(D97,District_Crime_Unit_Map!A:A,District_Crime_Unit_Map!B:B,"") -> Rajshahi Range | K97: =_xlfn.XLOOKUP(J97,Crime_Data!A:A,Crime_Data!V:V,"") -> 112.81411 | L97: =_xlfn.XLOOKUP(J97,Crime_Data!A:A,Crime_Data!W:W,"") -> 14.272851 | M97: =TRIM(Table6[[#This Row],[District]])&"|"&TRIM(Table6[[#This Row],[Upazila]]) -> Rajshahi|Rajshahi City Corporation | N97: =_xlfn.XLOOKUP(B97,Remittance_Data!A:A,Remittance_Data!B:B,"CHECK") -> CHECK | O97: =_xlfn.XLOOKUP(B97,Remittance_Data!A:A,Remittance_Data!C:C,"CHECK") -> CHECK | P97: =_xlfn.XLOOKUP(B97,Remittance_Data!A:A,Remittance_Data!D:D,"CHECK") -> CHECK
A98: Rajshahi-3 | B98: =SUBSTITUTE(SUBSTITUTE(SUBSTITUTE(SUBSTITUTE(TRIM(Table6[[#This Row],[Constituency]]),"Barisal","Barishal"),"Jessore","Jashore"),"Bogra","Bogura"),"Chapai Nawabganj","Chapainawabganj") -> Rajshahi-3 | C98: Paba | D98: Rajshahi | E98: =_xlfn.XLOOKUP(C98,Population_data!B:B,Population_data!C:C,"") -> 189.9 | F98: =_xlfn.XLOOKUP(C98,Population_data!B:B,Population_data!D:D,"") -> 368857 | G98: =_xlfn.XLOOKUP(C98,Population_data!B:B,Population_data!E:E,"") -> 1942.37 | H98: =_xlfn.XLOOKUP(C98,Population_data!B:B,Population_data!F:F,"") -> 3.74 | I98: =_xlfn.XLOOKUP(C98,Population_data!B:B,Population_data!G:G,"") -> 74.72 | J98: =_xlfn.XLOOKUP(D98,District_Crime_Unit_Map!A:A,District_Crime_Unit_Map!B:B,"") -> Rajshahi Range | K98: =_xlfn.XLOOKUP(J98,Crime_Data!A:A,Crime_Data!V:V,"") -> 112.81411 | L98: =_xlfn.XLOOKUP(J98,Crime_Data!A:A,Crime_Data!W:W,"") -> 14.272851 | M98: =TRIM(Table6[[#This Row],[District]])&"|"&TRIM(Table6[[#This Row],[Upazila]]) -> Rajshahi|Paba | N98: =_xlfn.XLOOKUP(B98,Remittance_Data!A:A,Remittance_Data!B:B,"CHECK") -> CHECK | O98: =_xlfn.XLOOKUP(B98,Remittance_Data!A:A,Remittance_Data!C:C,"CHECK") -> CHECK | P98: =_xlfn.XLOOKUP(B98,Remittance_Data!A:A,Remittance_Data!D:D,"CHECK") -> CHECK
A99: Rajshahi-3 | B99: =SUBSTITUTE(SUBSTITUTE(SUBSTITUTE(SUBSTITUTE(TRIM(Table6[[#This Row],[Constituency]]),"Barisal","Barishal"),"Jessore","Jashore"),"Bogra","Bogura"),"Chapai Nawabganj","Chapainawabganj") -> Rajshahi-3 | C99: Mohanpur | D99: Rajshahi | E99: =_xlfn.XLOOKUP(C99,Population_data!B:B,Population_data!C:C,"") -> 163.49 | F99: =_xlfn.XLOOKUP(C99,Population_data!B:B,Population_data!D:D,"") -> 186883 | G99: =_xlfn.XLOOKUP(C99,Population_data!B:B,Population_data!E:E,"") -> 1143.09 | H99: =_xlfn.XLOOKUP(C99,Population_data!B:B,Population_data!F:F,"") -> 3.52 | I99: =_xlfn.XLOOKUP(C99,Population_data!B:B,Population_data!G:G,"") -> 73.88 | J99: =_xlfn.XLOOKUP(D99,District_Crime_Unit_Map!A:A,District_Crime_Unit_Map!B:B,"") -> Rajshahi Range | K99: =_xlfn.XLOOKUP(J99,Crime_Data!A:A,Crime_Data!V:V,"") -> 112.81411 | L99: =_xlfn.XLOOKUP(J99,Crime_Data!A:A,Crime_Data!W:W,"") -> 14.272851 | M99: =TRIM(Table6[[#This Row],[District]])&"|"&TRIM(Table6[[#This Row],[Upazila]]) -> Rajshahi|Mohanpur | N99: =_xlfn.XLOOKUP(B99,Remittance_Data!A:A,Remittance_Data!B:B,"CHECK") -> CHECK | O99: =_xlfn.XLOOKUP(B99,Remittance_Data!A:A,Remittance_Data!C:C,"CHECK") -> CHECK | P99: =_xlfn.XLOOKUP(B99,Remittance_Data!A:A,Remittance_Data!D:D,"CHECK") -> CHECK
A100: Rajshahi-4 | B100: =SUBSTITUTE(SUBSTITUTE(SUBSTITUTE(SUBSTITUTE(TRIM(Table6[[#This Row],[Constituency]]),"Barisal","Barishal"),"Jessore","Jashore"),"Bogra","Bogura"),"Chapai Nawabganj","Chapainawabganj") -> Rajshahi-4 | C100: Bagmara | D100: Rajshahi | E100: =_xlfn.XLOOKUP(C100,Population_data!B:B,Population_data!C:C,"") -> 363.56 | F100: =_xlfn.XLOOKUP(C100,Population_data!B:B,Population_data!D:D,"") -> 373945 | G100: =_xlfn.XLOOKUP(C100,Population_data!B:B,Population_data!E:E,"") -> 1028.56 | H100: =_xlfn.XLOOKUP(C100,Population_data!B:B,Population_data!F:F,"") -> 3.5 | I100: =_xlfn.XLOOKUP(C100,Population_data!B:B,Population_data!G:G,"") -> 69.21 | J100: =_xlfn.XLOOKUP(D100,District_Crime_Unit_Map!A:A,District_Crime_Unit_Map!B:B,"") -> Rajshahi Range | K100: =_xlfn.XLOOKUP(J100,Crime_Data!A:A,Crime_Data!V:V,"") -> 112.81411 | L100: =_xlfn.XLOOKUP(J100,Crime_Data!A:A,Crime_Data!W:W,"") -> 14.272851 | M100: =TRIM(Table6[[#This Row],[District]])&"|"&TRIM(Table6[[#This Row],[Upazila]]) -> Rajshahi|Bagmara | N100: =_xlfn.XLOOKUP(B100,Remittance_Data!A:A,Remittance_Data!B:B,"CHECK") -> CHECK | O100: =_xlfn.XLOOKUP(B100,Remittance_Data!A:A,Remittance_Data!C:C,"CHECK") -> CHECK | P100: =_xlfn.XLOOKUP(B100,Remittance_Data!A:A,Remittance_Data!D:D,"CHECK") -> CHECK
A101: Rajshahi-5 | B101: =SUBSTITUTE(SUBSTITUTE(SUBSTITUTE(SUBSTITUTE(TRIM(Table6[[#This Row],[Constituency]]),"Barisal","Barishal"),"Jessore","Jashore"),"Bogra","Bogura"),"Chapai Nawabganj","Chapainawabganj") -> Rajshahi-5 | C101: Durgapur | D101: Rajshahi | E101: =_xlfn.XLOOKUP(C101,Population_data!B:B,Population_data!C:C,"") -> 335.46 | F101: =_xlfn.XLOOKUP(C101,Population_data!B:B,Population_data!D:D,"") -> 242445 | G101: =_xlfn.XLOOKUP(C101,Population_data!B:B,Population_data!E:E,"") -> 722.72 | H101: =_xlfn.XLOOKUP(C101,Population_data!B:B,Population_data!F:F,"") -> 4.08 | I101: =_xlfn.XLOOKUP(C101,Population_data!B:B,Population_data!G:G,"") -> 66.76 | J101: =_xlfn.XLOOKUP(D101,District_Crime_Unit_Map!A:A,District_Crime_Unit_Map!B:B,"") -> Rajshahi Range | K101: =_xlfn.XLOOKUP(J101,Crime_Data!A:A,Crime_Data!V:V,"") -> 112.81411 | L101: =_xlfn.XLOOKUP(J101,Crime_Data!A:A,Crime_Data!W:W,"") -> 14.272851 | M101: =TRIM(Table6[[#This Row],[District]])&"|"&TRIM(Table6[[#This Row],[Upazila]]) -> Rajshahi|Durgapur | N101: =_xlfn.XLOOKUP(B101,Remittance_Data!A:A,Remittance_Data!B:B,"CHECK") -> CHECK | O101: =_xlfn.XLOOKUP(B101,Remittance_Data!A:A,Remittance_Data!C:C,"CHECK") -> CHECK | P101: =_xlfn.XLOOKUP(B101,Remittance_Data!A:A,Remittance_Data!D:D,"CHECK") -> CHECK
A102: Rajshahi-5 | B102: =SUBSTITUTE(SUBSTITUTE(SUBSTITUTE(SUBSTITUTE(TRIM(Table6[[#This Row],[Constituency]]),"Barisal","Barishal"),"Jessore","Jashore"),"Bogra","Bogura"),"Chapai Nawabganj","Chapainawabganj") -> Rajshahi-5 | C102: Puthia | D102: Rajshahi | E102: =_xlfn.XLOOKUP(C102,Population_data!B:B,Population_data!C:C,"") -> 192.3 | F102: =_xlfn.XLOOKUP(C102,Population_data!B:B,Population_data!D:D,"") -> 224131 | G102: =_xlfn.XLOOKUP(C102,Population_data!B:B,Population_data!E:E,"") -> 1165.53 | H102: =_xlfn.XLOOKUP(C102,Population_data!B:B,Population_data!F:F,"") -> 3.57 | I102: =_xlfn.XLOOKUP(C102,Population_data!B:B,Population_data!G:G,"") -> 71.53 | J102: =_xlfn.XLOOKUP(D102,District_Crime_Unit_Map!A:A,District_Crime_Unit_Map!B:B,"") -> Rajshahi Range | K102: =_xlfn.XLOOKUP(J102,Crime_Data!A:A,Crime_Data!V:V,"") -> 112.81411 | L102: =_xlfn.XLOOKUP(J102,Crime_Data!A:A,Crime_Data!W:W,"") -> 14.272851 | M102: =TRIM(Table6[[#This Row],[District]])&"|"&TRIM(Table6[[#This Row],[Upazila]]) -> Rajshahi|Puthia | N102: =_xlfn.XLOOKUP(B102,Remittance_Data!A:A,Remittance_Data!B:B,"CHECK") -> CHECK | O102: =_xlfn.XLOOKUP(B102,Remittance_Data!A:A,Remittance_Data!C:C,"CHECK") -> CHECK | P102: =_xlfn.XLOOKUP(B102,Remittance_Data!A:A,Remittance_Data!D:D,"CHECK") -> CHECK
A103: Rajshahi-6 | B103: =SUBSTITUTE(SUBSTITUTE(SUBSTITUTE(SUBSTITUTE(TRIM(Table6[[#This Row],[Constituency]]),"Barisal","Barishal"),"Jessore","Jashore"),"Bogra","Bogura"),"Chapai Nawabganj","Chapainawabganj") -> Rajshahi-6 | C103: Bagha | D103: Rajshahi | E103: =_xlfn.XLOOKUP(C103,Population_data!B:B,Population_data!C:C,"") -> 272.67 | F103: =_xlfn.XLOOKUP(C103,Population_data!B:B,Population_data!D:D,"") -> 195886 | G103: =_xlfn.XLOOKUP(C103,Population_data!B:B,Population_data!E:E,"") -> 718.4 | H103: =_xlfn.XLOOKUP(C103,Population_data!B:B,Population_data!F:F,"") -> 3.63 | I103: =_xlfn.XLOOKUP(C103,Population_data!B:B,Population_data!G:G,"") -> 70.06 | J103: =_xlfn.XLOOKUP(D103,District_Crime_Unit_Map!A:A,District_Crime_Unit_Map!B:B,"") -> Rajshahi Range | K103: =_xlfn.XLOOKUP(J103,Crime_Data!A:A,Crime_Data!V:V,"") -> 112.81411 | L103: =_xlfn.XLOOKUP(J103,Crime_Data!A:A,Crime_Data!W:W,"") -> 14.272851 | M103: =TRIM(Table6[[#This Row],[District]])&"|"&TRIM(Table6[[#This Row],[Upazila]]) -> Rajshahi|Bagha | N103: =_xlfn.XLOOKUP(B103,Remittance_Data!A:A,Remittance_Data!B:B,"CHECK") -> CHECK | O103: =_xlfn.XLOOKUP(B103,Remittance_Data!A:A,Remittance_Data!C:C,"CHECK") -> CHECK | P103: =_xlfn.XLOOKUP(B103,Remittance_Data!A:A,Remittance_Data!D:D,"CHECK") -> CHECK
A104: Rajshahi-6 | B104: =SUBSTITUTE(SUBSTITUTE(SUBSTITUTE(SUBSTITUTE(TRIM(Table6[[#This Row],[Constituency]]),"Barisal","Barishal"),"Jessore","Jashore"),"Bogra","Bogura"),"Chapai Nawabganj","Chapainawabganj") -> Rajshahi-6 | C104: Charghat | D104: Rajshahi | E104: =_xlfn.XLOOKUP(C104,Population_data!B:B,Population_data!C:C,"") -> 133.32 | F104: =_xlfn.XLOOKUP(C104,Population_data!B:B,Population_data!D:D,"") -> 224833 | G104: =_xlfn.XLOOKUP(C104,Population_data!B:B,Population_data!E:E,"") -> 1686.42 | H104: =_xlfn.XLOOKUP(C104,Population_data!B:B,Population_data!F:F,"") -> 3.65 | I104: =_xlfn.XLOOKUP(C104,Population_data!B:B,Population_data!G:G,"") -> 70.99 | J104: =_xlfn.XLOOKUP(D104,District_Crime_Unit_Map!A:A,District_Crime_Unit_Map!B:B,"") -> Rajshahi Range | K104: =_xlfn.XLOOKUP(J104,Crime_Data!A:A,Crime_Data!V:V,"") -> 112.81411 | L104: =_xlfn.XLOOKUP(J104,Crime_Data!A:A,Crime_Data!W:W,"") -> 14.272851 | M104: =TRIM(Table6[[#This Row],[District]])&"|"&TRIM(Table6[[#This Row],[Upazila]]) -> Rajshahi|Charghat | N104: =_xlfn.XLOOKUP(B104,Remittance_Data!A:A,Remittance_Data!B:B,"CHECK") -> CHECK | O104: =_xlfn.XLOOKUP(B104,Remittance_Data!A:A,Remittance_Data!C:C,"CHECK") -> CHECK | P104: =_xlfn.XLOOKUP(B104,Remittance_Data!A:A,Remittance_Data!D:D,"CHECK") -> CHECK
A105: Natore-1 | B105: =SUBSTITUTE(SUBSTITUTE(SUBSTITUTE(SUBSTITUTE(TRIM(Table6[[#This Row],[Constituency]]),"Barisal","Barishal"),"Jessore","Jashore"),"Bogra","Bogura"),"Chapai Nawabganj","Chapainawabganj") -> Natore-1 | C105: Lalpur | D105: Natore | E105: =_xlfn.XLOOKUP(C105,Population_data!B:B,Population_data!C:C,"") -> 468.39 | F105: =_xlfn.XLOOKUP(C105,Population_data!B:B,Population_data!D:D,"") -> 306333 | G105: =_xlfn.XLOOKUP(C105,Population_data!B:B,Population_data!E:E,"") -> 654.01 | H105: =_xlfn.XLOOKUP(C105,Population_data!B:B,Population_data!F:F,"") -> 3.71 | I105: =_xlfn.XLOOKUP(C105,Population_data!B:B,Population_data!G:G,"") -> 72.6 | J105: =_xlfn.XLOOKUP(D105,District_Crime_Unit_Map!A:A,District_Crime_Unit_Map!B:B,"") -> Rajshahi Range | K105: =_xlfn.XLOOKUP(J105,Crime_Data!A:A,Crime_Data!V:V,"") -> 112.81411 | L105: =_xlfn.XLOOKUP(J105,Crime_Data!A:A,Crime_Data!W:W,"") -> 14.272851 | M105: =TRIM(Table6[[#This Row],[District]])&"|"&TRIM(Table6[[#This Row],[Upazila]]) -> Natore|Lalpur | N105: =_xlfn.XLOOKUP(B105,Remittance_Data!A:A,Remittance_Data!B:B,"CHECK") -> CHECK | O105: =_xlfn.XLOOKUP(B105,Remittance_Data!A:A,Remittance_Data!C:C,"CHECK") -> CHECK | P105: =_xlfn.XLOOKUP(B105,Remittance_Data!A:A,Remittance_Data!D:D,"CHECK") -> CHECK
A106: Natore-1 | B106: =SUBSTITUTE(SUBSTITUTE(SUBSTITUTE(SUBSTITUTE(TRIM(Table6[[#This Row],[Constituency]]),"Barisal","Barishal"),"Jessore","Jashore"),"Bogra","Bogura"),"Chapai Nawabganj","Chapainawabganj") -> Natore-1 | C106: Bagatipara | D106: Natore | E106: =_xlfn.XLOOKUP(C106,Population_data!B:B,Population_data!C:C,"") -> 205.7 | F106: =_xlfn.XLOOKUP(C106,Population_data!B:B,Population_data!D:D,"") -> 140691 | G106: =_xlfn.XLOOKUP(C106,Population_data!B:B,Population_data!E:E,"") -> 683.96 | H106: =_xlfn.XLOOKUP(C106,Population_data!B:B,Population_data!F:F,"") -> 3.58 | I106: =_xlfn.XLOOKUP(C106,Population_data!B:B,Population_data!G:G,"") -> 75.25 | J106: =_xlfn.XLOOKUP(D106,District_Crime_Unit_Map!A:A,District_Crime_Unit_Map!B:B,"") -> Rajshahi Range | K106: =_xlfn.XLOOKUP(J106,Crime_Data!A:A,Crime_Data!V:V,"") -> 112.81411 | L106: =_xlfn.XLOOKUP(J106,Crime_Data!A:A,Crime_Data!W:W,"") -> 14.272851 | M106: =TRIM(Table6[[#This Row],[District]])&"|"&TRIM(Table6[[#This Row],[Upazila]]) -> Natore|Bagatipara | N106: =_xlfn.XLOOKUP(B106,Remittance_Data!A:A,Remittance_Data!B:B,"CHECK") -> CHECK | O106: =_xlfn.XLOOKUP(B106,Remittance_Data!A:A,Remittance_Data!C:C,"CHECK") -> CHECK | P106: =_xlfn.XLOOKUP(B106,Remittance_Data!A:A,Remittance_Data!D:D,"CHECK") -> CHECK
A107: Natore-2 | B107: =SUBSTITUTE(SUBSTITUTE(SUBSTITUTE(SUBSTITUTE(TRIM(Table6[[#This Row],[Constituency]]),"Barisal","Barishal"),"Jessore","Jashore"),"Bogra","Bogura"),"Chapai Nawabganj","Chapainawabganj") -> Natore-2 | C107: Natore Sadar | D107: Natore | E107: =_xlfn.XLOOKUP(C107,Population_data!B:B,Population_data!C:C,"") -> 278.33 | F107: =_xlfn.XLOOKUP(C107,Population_data!B:B,Population_data!D:D,"") -> 352967 | G107: =_xlfn.XLOOKUP(C107,Population_data!B:B,Population_data!E:E,"") -> 1268.16 | H107: =_xlfn.XLOOKUP(C107,Population_data!B:B,Population_data!F:F,"") -> 3.67 | I107: =_xlfn.XLOOKUP(C107,Population_data!B:B,Population_data!G:G,"") -> 75.2 | J107: =_xlfn.XLOOKUP(D107,District_Crime_Unit_Map!A:A,District_Crime_Unit_Map!B:B,"") -> Rajshahi Range | K107: =_xlfn.XLOOKUP(J107,Crime_Data!A:A,Crime_Data!V:V,"") -> 112.81411 | L107: =_xlfn.XLOOKUP(J107,Crime_Data!A:A,Crime_Data!W:W,"") -> 14.272851 | M107: =TRIM(Table6[[#This Row],[District]])&"|"&TRIM(Table6[[#This Row],[Upazila]]) -> Natore|Natore Sadar | N107: =_xlfn.XLOOKUP(B107,Remittance_Data!A:A,Remittance_Data!B:B,"CHECK") -> CHECK | O107: =_xlfn.XLOOKUP(B107,Remittance_Data!A:A,Remittance_Data!C:C,"CHECK") -> CHECK | P107: =_xlfn.XLOOKUP(B107,Remittance_Data!A:A,Remittance_Data!D:D,"CHECK") -> CHECK
A108: Natore-3 | B108: =SUBSTITUTE(SUBSTITUTE(SUBSTITUTE(SUBSTITUTE(TRIM(Table6[[#This Row],[Constituency]]),"Barisal","Barishal"),"Jessore","Jashore"),"Bogra","Bogura"),"Chapai Nawabganj","Chapainawabganj") -> Natore-3 | C108: Singra | D108: Natore | E108: =_xlfn.XLOOKUP(C108,Population_data!B:B,Population_data!C:C,"") -> 279.14 | F108: =_xlfn.XLOOKUP(C108,Population_data!B:B,Population_data!D:D,"") -> 381301 | G108: =_xlfn.XLOOKUP(C108,Population_data!B:B,Population_data!E:E,"") -> 1365.98 | H108: =_xlfn.XLOOKUP(C108,Population_data!B:B,Population_data!F:F,"") -> 3.72 | I108: =_xlfn.XLOOKUP(C108,Population_data!B:B,Population_data!G:G,"") -> 66.95 | J108: =_xlfn.XLOOKUP(D108,District_Crime_Unit_Map!A:A,District_Crime_Unit_Map!B:B,"") -> Rajshahi Range | K108: =_xlfn.XLOOKUP(J108,Crime_Data!A:A,Crime_Data!V:V,"") -> 112.81411 | L108: =_xlfn.XLOOKUP(J108,Crime_Data!A:A,Crime_Data!W:W,"") -> 14.272851 | M108: =TRIM(Table6[[#This Row],[District]])&"|"&TRIM(Table6[[#This Row],[Upazila]]) -> Natore|Singra | N108: =_xlfn.XLOOKUP(B108,Remittance_Data!A:A,Remittance_Data!B:B,"CHECK") -> CHECK | O108: =_xlfn.XLOOKUP(B108,Remittance_Data!A:A,Remittance_Data!C:C,"CHECK") -> CHECK | P108: =_xlfn.XLOOKUP(B108,Remittance_Data!A:A,Remittance_Data!D:D,"CHECK") -> CHECK
A109: Natore-3 | B109: =SUBSTITUTE(SUBSTITUTE(SUBSTITUTE(SUBSTITUTE(TRIM(Table6[[#This Row],[Constituency]]),"Barisal","Barishal"),"Jessore","Jashore"),"Bogra","Bogura"),"Chapai Nawabganj","Chapainawabganj") -> Natore-3 | C109: Gurudaspur | D109: Natore | E109: =_xlfn.XLOOKUP(C109,Population_data!B:B,Population_data!C:C,"") -> 327.92 | F109: =_xlfn.XLOOKUP(C109,Population_data!B:B,Population_data!D:D,"") -> 234328 | G109: =_xlfn.XLOOKUP(C109,Population_data!B:B,Population_data!E:E,"") -> 714.59 | H109: =_xlfn.XLOOKUP(C109,Population_data!B:B,Population_data!F:F,"") -> 3.6 | I109: =_xlfn.XLOOKUP(C109,Population_data!B:B,Population_data!G:G,"") -> 68.97 | J109: =_xlfn.XLOOKUP(D109,District_Crime_Unit_Map!A:A,District_Crime_Unit_Map!B:B,"") -> Rajshahi Range | K109: =_xlfn.XLOOKUP(J109,Crime_Data!A:A,Crime_Data!V:V,"") -> 112.81411 | L109: =_xlfn.XLOOKUP(J109,Crime_Data!A:A,Crime_Data!W:W,"") -> 14.272851 | M109: =TRIM(Table6[[#This Row],[District]])&"|"&TRIM(Table6[[#This Row],[Upazila]]) -> Natore|Gurudaspur | N109: =_xlfn.XLOOKUP(B109,Remittance_Data!A:A,Remittance_Data!B:B,"CHECK") -> CHECK | O109: =_xlfn.XLOOKUP(B109,Remittance_Data!A:A,Remittance_Data!C:C,"CHECK") -> CHECK | P109: =_xlfn.XLOOKUP(B109,Remittance_Data!A:A,Remittance_Data!D:D,"CHECK") -> CHECK
... A175: Khulna-6 | B175: =SUBSTITUTE(SUBSTITUTE(SUBSTITUTE(SUBSTITUTE(TRIM(Table6[[#This Row],[Constituency]]),"Barisal","Barishal"),"Jessore","Jashore"),"Bogra","Bogura"),"Chapai Nawabganj","Chapainawabganj") -> Khulna-6 | C175: Koyra | D175: Khulna | E175: =_xlfn.XLOOKUP(C175,Population_data!B:B,Population_data!C:C,"") -> 1775.41 | F175: =_xlfn.XLOOKUP(C175,Population_data!B:B,Population_data!D:D,"") -> 220092 | G175: =_xlfn.XLOOKUP(C175,Population_data!B:B,Population_data!E:E,"") -> 123.97 | H175: =_xlfn.XLOOKUP(C175,Population_data!B:B,Population_data!F:F,"") -> 3.96 | I175: =_xlfn.XLOOKUP(C175,Population_data!B:B,Population_data!G:G,"") -> 76.09 | J175: =_xlfn.XLOOKUP(D175,District_Crime_Unit_Map!A:A,District_Crime_Unit_Map!B:B,"") -> Khulna Range | K175: =_xlfn.XLOOKUP(J175,Crime_Data!A:A,Crime_Data!V:V,"") -> 102.32166 | L175: =_xlfn.XLOOKUP(J175,Crime_Data!A:A,Crime_Data!W:W,"") -> 12.212238 | M175: =TRIM(Table6[[#This Row],[District]])&"|"&TRIM(Table6[[#This Row],[Upazila]]) -> Khulna|Koyra | N175: =_xlfn.XLOOKUP(B175,Remittance_Data!A:A,Remittance_Data!B:B,"CHECK") -> CHECK | O175: =_xlfn.XLOOKUP(B175,Remittance_Data!A:A,Remittance_Data!C:C,"CHECK") -> CHECK | P175: =_xlfn.XLOOKUP(B175,Remittance_Data!A:A,Remittance_Data!D:D,"CHECK") -> CHECK
A176: Khulna-2 | B176: =SUBSTITUTE(SUBSTITUTE(SUBSTITUTE(SUBSTITUTE(TRIM(Table6[[#This Row],[Constituency]]),"Barisal","Barishal"),"Jessore","Jashore"),"Bogra","Bogura"),"Chapai Nawabganj","Chapainawabganj") -> Khulna-2 | C176: Khulna City Corporation | D176: Khulna | E176: 22.83 | F176: 359779 | G176: 15762 | H176: 3.75 | I176: 88.07 | J176: =_xlfn.XLOOKUP(D176,District_Crime_Unit_Map!A:A,District_Crime_Unit_Map!B:B,"") -> Khulna Range | K176: =_xlfn.XLOOKUP(J176,Crime_Data!A:A,Crime_Data!V:V,"") -> 102.32166 | L176: =_xlfn.XLOOKUP(J176,Crime_Data!A:A,Crime_Data!W:W,"") -> 12.212238 | M176: =TRIM(Table6[[#This Row],[District]])&"|"&TRIM(Table6[[#This Row],[Upazila]]) -> Khulna|Khulna City Corporation | N176: =_xlfn.XLOOKUP(B176,Remittance_Data!A:A,Remittance_Data!B:B,"CHECK") -> CHECK | O176: =_xlfn.XLOOKUP(B176,Remittance_Data!A:A,Remittance_Data!C:C,"CHECK") -> CHECK | P176: =_xlfn.XLOOKUP(B176,Remittance_Data!A:A,Remittance_Data!D:D,"CHECK") -> CHECK
A177: Khulna-4 | B177: =SUBSTITUTE(SUBSTITUTE(SUBSTITUTE(SUBSTITUTE(TRIM(Table6[[#This Row],[Constituency]]),"Barisal","Barishal"),"Jessore","Jashore"),"Bogra","Bogura"),"Chapai Nawabganj","Chapainawabganj") -> Khulna-4 | C177: Terokhada | D177: Khulna | E177: =_xlfn.XLOOKUP(C177,Population_data!B:B,Population_data!C:C,"") -> 189.48 | F177: =_xlfn.XLOOKUP(C177,Population_data!B:B,Population_data!D:D,"") -> 128922 | G177: =_xlfn.XLOOKUP(C177,Population_data!B:B,Population_data!E:E,"") -> 680.4 | H177: =_xlfn.XLOOKUP(C177,Population_data!B:B,Population_data!F:F,"") -> 3.97 | I177: =_xlfn.XLOOKUP(C177,Population_data!B:B,Population_data!G:G,"") -> 73.19 | J177: =_xlfn.XLOOKUP(D177,District_Crime_Unit_Map!A:A,District_Crime_Unit_Map!B:B,"") -> Khulna Range | K177: =_xlfn.XLOOKUP(J177,Crime_Data!A:A,Crime_Data!V:V,"") -> 102.32166 | L177: =_xlfn.XLOOKUP(J177,Crime_Data!A:A,Crime_Data!W:W,"") -> 12.212238 | M177: =TRIM(Table6[[#This Row],[District]])&"|"&TRIM(Table6[[#This Row],[Upazila]]) -> Khulna|Terokhada | N177: =_xlfn.XLOOKUP(B177,Remittance_Data!A:A,Remittance_Data!B:B,"CHECK") -> CHECK | O177: =_xlfn.XLOOKUP(B177,Remittance_Data!A:A,Remittance_Data!C:C,"CHECK") -> CHECK | P177: =_xlfn.XLOOKUP(B177,Remittance_Data!A:A,Remittance_Data!D:D,"CHECK") -> CHECK
A178: Khulna-3 | B178: =SUBSTITUTE(SUBSTITUTE(SUBSTITUTE(SUBSTITUTE(TRIM(Table6[[#This Row],[Constituency]]),"Barisal","Barishal"),"Jessore","Jashore"),"Bogra","Bogura"),"Chapai Nawabganj","Chapainawabganj") -> Khulna-3 | C178: Khulna City Corporation | D178: Khulna | E178: 22.83 | F178: 359779 | G178: 15762 | H178: 3.75 | I178: 88.07 | J178: =_xlfn.XLOOKUP(D178,District_Crime_Unit_Map!A:A,District_Crime_Unit_Map!B:B,"") -> Khulna Range | K178: =_xlfn.XLOOKUP(J178,Crime_Data!A:A,Crime_Data!V:V,"") -> 102.32166 | L178: =_xlfn.XLOOKUP(J178,Crime_Data!A:A,Crime_Data!W:W,"") -> 12.212238 | M178: =TRIM(Table6[[#This Row],[District]])&"|"&TRIM(Table6[[#This Row],[Upazila]]) -> Khulna|Khulna City Corporation | N178: =_xlfn.XLOOKUP(B178,Remittance_Data!A:A,Remittance_Data!B:B,"CHECK") -> CHECK | O178: =_xlfn.XLOOKUP(B178,Remittance_Data!A:A,Remittance_Data!C:C,"CHECK") -> CHECK | P178: =_xlfn.XLOOKUP(B178,Remittance_Data!A:A,Remittance_Data!D:D,"CHECK") -> CHECK
A179: Khulna-4 | B179: =SUBSTITUTE(SUBSTITUTE(SUBSTITUTE(SUBSTITUTE(TRIM(Table6[[#This Row],[Constituency]]),"Barisal","Barishal"),"Jessore","Jashore"),"Bogra","Bogura"),"Chapai Nawabganj","Chapainawabganj") -> Khulna-4 | C179: Rupsa | D179: Khulna | E179: =_xlfn.XLOOKUP(C179,Population_data!B:B,Population_data!C:C,"") -> 120.15 | F179: =_xlfn.XLOOKUP(C179,Population_data!B:B,Population_data!D:D,"") -> 206744 | G179: =_xlfn.XLOOKUP(C179,Population_data!B:B,Population_data!E:E,"") -> 1720.72 | H179: =_xlfn.XLOOKUP(C179,Population_data!B:B,Population_data!F:F,"") -> 3.91 | I179: =_xlfn.XLOOKUP(C179,Population_data!B:B,Population_data!G:G,"") -> 80.04 | J179: =_xlfn.XLOOKUP(D179,District_Crime_Unit_Map!A:A,District_Crime_Unit_Map!B:B,"") -> Khulna Range | K179: =_xlfn.XLOOKUP(J179,Crime_Data!A:A,Crime_Data!V:V,"") -> 102.32166 | L179: =_xlfn.XLOOKUP(J179,Crime_Data!A:A,Crime_Data!W:W,"") -> 12.212238 | M179: =TRIM(Table6[[#This Row],[District]])&"|"&TRIM(Table6[[#This Row],[Upazila]]) -> Khulna|Rupsa | N179: =_xlfn.XLOOKUP(B179,Remittance_Data!A:A,Remittance_Data!B:B,"CHECK") -> CHECK | O179: =_xlfn.XLOOKUP(B179,Remittance_Data!A:A,Remittance_Data!C:C,"CHECK") -> CHECK | P179: =_xlfn.XLOOKUP(B179,Remittance_Data!A:A,Remittance_Data!D:D,"CHECK") -> CHECK
A180: Khulna-4 | B180: =SUBSTITUTE(SUBSTITUTE(SUBSTITUTE(SUBSTITUTE(TRIM(Table6[[#This Row],[Constituency]]),"Barisal","Barishal"),"Jessore","Jashore"),"Bogra","Bogura"),"Chapai Nawabganj","Chapainawabganj") -> Khulna-4 | C180: Dighalia | D180: Khulna | E180: =_xlfn.XLOOKUP(C180,Population_data!B:B,Population_data!C:C,"") -> 177.76 | F180: =_xlfn.XLOOKUP(C180,Population_data!B:B,Population_data!D:D,"") -> 167013 | G180: =_xlfn.XLOOKUP(C180,Population_data!B:B,Population_data!E:E,"") -> 939.54 | H180: =_xlfn.XLOOKUP(C180,Population_data!B:B,Population_data!F:F,"") -> 4 | I180: =_xlfn.XLOOKUP(C180,Population_data!B:B,Population_data!G:G,"") -> 81.68 | J180: =_xlfn.XLOOKUP(D180,District_Crime_Unit_Map!A:A,District_Crime_Unit_Map!B:B,"") -> Khulna Range | K180: =_xlfn.XLOOKUP(J180,Crime_Data!A:A,Crime_Data!V:V,"") -> 102.32166 | L180: =_xlfn.XLOOKUP(J180,Crime_Data!A:A,Crime_Data!W:W,"") -> 12.212238 | M180: =TRIM(Table6[[#This Row],[District]])&"|"&TRIM(Table6[[#This Row],[Upazila]]) -> Khulna|Dighalia | N180: =_xlfn.XLOOKUP(B180,Remittance_Data!A:A,Remittance_Data!B:B,"CHECK") -> CHECK | O180: =_xlfn.XLOOKUP(B180,Remittance_Data!A:A,Remittance_Data!C:C,"CHECK") -> CHECK | P180: =_xlfn.XLOOKUP(B180,Remittance_Data!A:A,Remittance_Data!D:D,"CHECK") -> CHECK
A181: Khulna-5 | B181: =SUBSTITUTE(SUBSTITUTE(SUBSTITUTE(SUBSTITUTE(TRIM(Table6[[#This Row],[Constituency]]),"Barisal","Barishal"),"Jessore","Jashore"),"Bogra","Bogura"),"Chapai Nawabganj","Chapainawabganj") -> Khulna-5 | C181: Phultala | D181: Khulna | E181: =_xlfn.XLOOKUP(C181,Population_data!B:B,Population_data!C:C,"") -> 130.76 | F181: =_xlfn.XLOOKUP(C181,Population_data!B:B,Population_data!D:D,"") -> 148502 | G181: =_xlfn.XLOOKUP(C181,Population_data!B:B,Population_data!E:E,"") -> 1135.68 | H181: =_xlfn.XLOOKUP(C181,Population_data!B:B,Population_data!F:F,"") -> 3.86 | I181: =_xlfn.XLOOKUP(C181,Population_data!B:B,Population_data!G:G,"") -> 81.9 | J181: =_xlfn.XLOOKUP(D181,District_Crime_Unit_Map!A:A,District_Crime_Unit_Map!B:B,"") -> Khulna Range | K181: =_xlfn.XLOOKUP(J181,Crime_Data!A:A,Crime_Data!V:V,"") -> 102.32166 | L181: =_xlfn.XLOOKUP(J181,Crime_Data!A:A,Crime_Data!W:W,"") -> 12.212238 | M181: =TRIM(Table6[[#This Row],[District]])&"|"&TRIM(Table6[[#This Row],[Upazila]]) -> Khulna|Phultala | N181: =_xlfn.XLOOKUP(B181,Remittance_Data!A:A,Remittance_Data!B:B,"CHECK") -> CHECK | O181: =_xlfn.XLOOKUP(B181,Remittance_Data!A:A,Remittance_Data!C:C,"CHECK") -> CHECK | P181: =_xlfn.XLOOKUP(B181,Remittance_Data!A:A,Remittance_Data!D:D,"CHECK") -> CHECK
A182: Khulna-5 | B182: =SUBSTITUTE(SUBSTITUTE(SUBSTITUTE(SUBSTITUTE(TRIM(Table6[[#This Row],[Constituency]]),"Barisal","Barishal"),"Jessore","Jashore"),"Bogra","Bogura"),"Chapai Nawabganj","Chapainawabganj") -> Khulna-5 | C182: Dumuria | D182: Khulna | E182: =_xlfn.XLOOKUP(C182,Population_data!B:B,Population_data!C:C,"") -> 108.64 | F182: =_xlfn.XLOOKUP(C182,Population_data!B:B,Population_data!D:D,"") -> 343885 | G182: =_xlfn.XLOOKUP(C182,Population_data!B:B,Population_data!E:E,"") -> 3165.36 | H182: =_xlfn.XLOOKUP(C182,Population_data!B:B,Population_data!F:F,"") -> 3.87 | I182: =_xlfn.XLOOKUP(C182,Population_data!B:B,Population_data!G:G,"") -> 75.97 | J182: =_xlfn.XLOOKUP(D182,District_Crime_Unit_Map!A:A,District_Crime_Unit_Map!B:B,"") -> Khulna Range | K182: =_xlfn.XLOOKUP(J182,Crime_Data!A:A,Crime_Data!V:V,"") -> 102.32166 | L182: =_xlfn.XLOOKUP(J182,Crime_Data!A:A,Crime_Data!W:W,"") -> 12.212238 | M182: =TRIM(Table6[[#This Row],[District]])&"|"&TRIM(Table6[[#This Row],[Upazila]]) -> Khulna|Dumuria | N182: =_xlfn.XLOOKUP(B182,Remittance_Data!A:A,Remittance_Data!B:B,"CHECK") -> CHECK | O182: =_xlfn.XLOOKUP(B182,Remittance_Data!A:A,Remittance_Data!C:C,"CHECK") -> CHECK | P182: =_xlfn.XLOOKUP(B182,Remittance_Data!A:A,Remittance_Data!D:D,"CHECK") -> CHECK
A183: Satkhira-1 | B183: =SUBSTITUTE(SUBSTITUTE(SUBSTITUTE(SUBSTITUTE(TRIM(Table6[[#This Row],[Constituency]]),"Barisal","Barishal"),"Jessore","Jashore"),"Bogra","Bogura"),"Chapai Nawabganj","Chapainawabganj") -> Satkhira-1 | C183: Tala | D183: Satkhira | E183: =_xlfn.XLOOKUP(C183,Population_data!B:B,Population_data!C:C,"") -> 196.42 | F183: =_xlfn.XLOOKUP(C183,Population_data!B:B,Population_data!D:D,"") -> 326101 | G183: =_xlfn.XLOOKUP(C183,Population_data!B:B,Population_data!E:E,"") -> 1660.22 | H183: =_xlfn.XLOOKUP(C183,Population_data!B:B,Population_data!F:F,"") -> 3.79 | I183: =_xlfn.XLOOKUP(C183,Population_data!B:B,Population_data!G:G,"") -> 74.28 | J183: =_xlfn.XLOOKUP(D183,District_Crime_Unit_Map!A:A,District_Crime_Unit_Map!B:B,"") -> Khulna Range | K183: =_xlfn.XLOOKUP(J183,Crime_Data!A:A,Crime_Data!V:V,"") -> 102.32166 | L183: =_xlfn.XLOOKUP(J183,Crime_Data!A:A,Crime_Data!W:W,"") -> 12.212238 | M183: =TRIM(Table6[[#This Row],[District]])&"|"&TRIM(Table6[[#This Row],[Upazila]]) -> Satkhira|Tala | N183: =_xlfn.XLOOKUP(B183,Remittance_Data!A:A,Remittance_Data!B:B,"CHECK") -> CHECK | O183: =_xlfn.XLOOKUP(B183,Remittance_Data!A:A,Remittance_Data!C:C,"CHECK") -> CHECK | P183: =_xlfn.XLOOKUP(B183,Remittance_Data!A:A,Remittance_Data!D:D,"CHECK") -> CHECK
